Workbook
Name AnnualRentGrowth: [1]Input!$L$54:$P$54
Name AnnualRentGrowth: [1]Input!$L$54:$P$54
Name AnnualRentGrowth: [1]Input!$L$54:$P$54
Name AnnualRentGrowth: [1]Input!$L$54:$P$54
Name AnnualRentGrowth: [1]Input!$L$54:$P$54
Name AnnualRentGrowth: [1]Input!$L$54:$P$54
Name AnnualRentGrowth: [1]Input!$L$54:$P$54
Name AnnualRentGrowth: [1]Input!$L$54:$P$54
Name AnnualRentGrowth: [1]Input!$L$54:$P$54
Name AnnualRentGrowth: [1]Input!$L$54:$P$54
Name AssedValuePerc: [1]Input!$L$96
Name AssedValuePerc: [1]Input!$L$96
Name AssedValuePerc: [1]Input!$L$96
Name AssedValuePerc: [1]Input!$L$96
Name AssedValuePerc: [1]Input!$L$96
Name AssedValuePerc: [1]Input!$L$96
Name AssedValuePerc: [1]Input!$L$96
Name AssedValuePerc: [1]Input!$L$96
Name AssedValuePerc: [1]Input!$L$96
Name AssedValuePerc: [1]Input!$L$96
Name BadDebt: [1]Input!$L$49:$P$49
Name BadDebt: [1]Input!$L$49:$P$49
Name BadDebt: [1]Input!$L$49:$P$49
Name BadDebt: [1]Input!$L$49:$P$49
Name BadDebt: [1]Input!$L$49:$P$49
Name BadDebt: [1]Input!$L$49:$P$49
Name BadDebt: [1]Input!$L$49:$P$49
Name BadDebt: [1]Input!$L$49:$P$49
Name BadDebt: [1]Input!$L$49:$P$49
Name BadDebt: [1]Input!$L$49:$P$49
Name CashRateMezz: [1]Input!$E$43
Name CashRateMezz: [1]Input!$E$43
Name CashRateMezz: [1]Input!$E$43
Name CashRateMezz: [1]Input!$E$43
Name CashRateMezz: [1]Input!$E$43
Name CashRateMezz: [1]Input!$E$43
Name CashRateMezz: [1]Input!$E$43
Name CashRateMezz: [1]Input!$E$43
Name CashRateMezz: [1]Input!$E$43
Name CashRateMezz: [1]Input!$E$43
Name CircuitBreaker: [1]Input!$B$12
Name CircuitBreaker: [1]Input!$B$12
Name CircuitBreaker: [1]Input!$B$12
Name CircuitBreaker: [1]Input!$B$12
Name CircuitBreaker: [1]Input!$B$12
Name CircuitBreaker: [1]Input!$B$12
Name CircuitBreaker: [1]Input!$B$12
Name CircuitBreaker: [1]Input!$B$12
Name CircuitBreaker: [1]Input!$B$12
Name CircuitBreaker: [1]Input!$B$12
Name Concessions: [1]Input!$L$50:$P$50
Name Concessions: [1]Input!$L$50:$P$50
Name Concessions: [1]Input!$L$50:$P$50
Name Concessions: [1]Input!$L$50:$P$50
Name Concessions: [1]Input!$L$50:$P$50
Name Concessions: [1]Input!$L$50:$P$50
Name Concessions: [1]Input!$L$50:$P$50
Name Concessions: [1]Input!$L$50:$P$50
Name Concessions: [1]Input!$L$50:$P$50
Name Concessions: [1]Input!$L$50:$P$50

Sheet Portfolio Level Dashboards-->

Sheet Senior Maturity Tracker
B2: Fund | C2: Fund 1
B5: Deal Name | C5: Loan Amount | D5: Initial Maturity | E5: Extensions | F5: Extended Maturity (If Passing) | G5: DSCR Test | H5: Forecasted DSCR | I5: DY Test | J5: Forecasted DY | K5: Estimated Refinance Proceeds | L5: Implied Shortfall/ Paydown | M5: 2025 | Q5: 2026 | U5: 2027 | Y5: 2028
M6: 45747 | N6: =EOMONTH(M6,3) -> 45838 | O6: =EOMONTH(N6,3) -> 45930 | P6: =EOMONTH(O6,3) -> 46022 | Q6: =EOMONTH(P6,3) -> 46112 | R6: =EOMONTH(Q6,3) -> 46203 | S6: =EOMONTH(R6,3) -> 46295 | T6: =EOMONTH(S6,3) -> 46387 | U6: =EOMONTH(T6,3) -> 46477 | ... AB6: =EOMONTH(AA6,3) -> 47118
B7: Riverwalk Flats | C7: 50000000 | D7: 46228 | F7: 46228 | G7: 1.2 | H7: 1 | I7: 0.08 | J7: 0.08 | K7: =C7-500000 -> 49500000 | L7: =C7-K7 -> 500000 | M7: =IF(AND($F7>=M$6-90,$F7<M$6),$L7,0) -> 0 | N7: =IF(AND($F7>=N$6-90,$F7<N$6),$L7,0) -> 0 | O7: =IF(AND($F7>=O$6-90,$F7<O$6),$L7,0) -> 0 | P7: =IF(AND($F7>=P$6-90,$F7<P$6),$L7,0) -> 0 | Q7: =IF(AND($F7>=Q$6-90,$F7<Q$6),$L7,0) -> 0 | R7: =IF(AND($F7>=R$6-90,$F7<R$6),$L7,0) -> 0 | S7: =IF(AND($F7>=S$6-90,$F7<S$6),$L7,0) -> 500000 | T7: =IF(AND($F7>=T$6-90,$F7<T$6),$L7,0) -> 0 | ... AB7: =IF(AND($F7>=AB$6-90,$F7<AB$6),$L7,0) -> 0
B8: Harborlight Apartments | C8: 50000000 | D8: 46687 | F8: 46687 | G8: 1.2 | H8: 1 | I8: 0.08 | J8: 0.08 | K8: =C8-500000 -> 49500000 | L8: =C8-K8 -> 500000 | M8: =IF(AND($F8>=M$6-90,$F8<M$6),$L8,0) -> 0 | N8: =IF(AND($F8>=N$6-90,$F8<N$6),$L8,0) -> 0 | O8: =IF(AND($F8>=O$6-90,$F8<O$6),$L8,0) -> 0 | P8: =IF(AND($F8>=P$6-90,$F8<P$6),$L8,0) -> 0 | Q8: =IF(AND($F8>=Q$6-90,$F8<Q$6),$L8,0) -> 0 | R8: =IF(AND($F8>=R$6-90,$F8<R$6),$L8,0) -> 0 | S8: =IF(AND($F8>=S$6-90,$F8<S$6),$L8,0) -> 0 | T8: =IF(AND($F8>=T$6-90,$F8<T$6),$L8,0) -> 0 | ... AB8: =IF(AND($F8>=AB$6-90,$F8<AB$6),$L8,0) -> 0
B9: The Parkhaven | C9: 50000000 | D9: 46713 | F9: 46713 | G9: 1.2 | H9: 1 | I9: 0.08 | J9: 0.08 | K9: =C9-500000 -> 49500000 | L9: =C9-K9 -> 500000 | M9: =IF(AND($F9>=M$6-90,$F9<M$6),$L9,0) -> 0 | N9: =IF(AND($F9>=N$6-90,$F9<N$6),$L9,0) -> 0 | O9: =IF(AND($F9>=O$6-90,$F9<O$6),$L9,0) -> 0 | P9: =IF(AND($F9>=P$6-90,$F9<P$6),$L9,0) -> 0 | Q9: =IF(AND($F9>=Q$6-90,$F9<Q$6),$L9,0) -> 0 | R9: =IF(AND($F9>=R$6-90,$F9<R$6),$L9,0) -> 0 | S9: =IF(AND($F9>=S$6-90,$F9<S$6),$L9,0) -> 0 | T9: =IF(AND($F9>=T$6-90,$F9<T$6),$L9,0) -> 0 | ... AB9: =IF(AND($F9>=AB$6-90,$F9<AB$6),$L9,0) -> 0
B10: Golden Oak Terrace | C10: 50000000 | D10: 46768 | F10: 46768 | G10: 1.2 | H10: 1 | I10: 0.08 | J10: 0.08 | K10: =C10-500000 -> 49500000 | L10: =C10-K10 -> 500000 | M10: =IF(AND($F10>=M$6-90,$F10<M$6),$L10,0) -> 0 | N10: =IF(AND($F10>=N$6-90,$F10<N$6),$L10,0) -> 0 | O10: =IF(AND($F10>=O$6-90,$F10<O$6),$L10,0) -> 0 | P10: =IF(AND($F10>=P$6-90,$F10<P$6),$L10,0) -> 0 | Q10: =IF(AND($F10>=Q$6-90,$F10<Q$6),$L10,0) -> 0 | R10: =IF(AND($F10>=R$6-90,$F10<R$6),$L10,0) -> 0 | S10: =IF(AND($F10>=S$6-90,$F10<S$6),$L10,0) -> 0 | T10: =IF(AND($F10>=T$6-90,$F10<T$6),$L10,0) -> 0 | ... AB10: =IF(AND($F10>=AB$6-90,$F10<AB$6),$L10,0) -> 0
B11: Aurora Heights | C11: 50000000 | D11: 46891 | F11: 46891 | G11: 1.2 | H11: 1 | I11: 0.08 | J11: 0.08 | K11: =C11-500000 -> 49500000 | L11: =C11-K11 -> 500000 | M11: =IF(AND($F11>=M$6-90,$F11<M$6),$L11,0) -> 0 | N11: =IF(AND($F11>=N$6-90,$F11<N$6),$L11,0) -> 0 | O11: =IF(AND($F11>=O$6-90,$F11<O$6),$L11,0) -> 0 | P11: =IF(AND($F11>=P$6-90,$F11<P$6),$L11,0) -> 0 | Q11: =IF(AND($F11>=Q$6-90,$F11<Q$6),$L11,0) -> 0 | R11: =IF(AND($F11>=R$6-90,$F11<R$6),$L11,0) -> 0 | S11: =IF(AND($F11>=S$6-90,$F11<S$6),$L11,0) -> 0 | T11: =IF(AND($F11>=T$6-90,$F11<T$6),$L11,0) -> 0 | ... AB11: =IF(AND($F11>=AB$6-90,$F11<AB$6),$L11,0) -> 0
B12: The Summit at Westview | C12: 50000000 | D12: 46929 | F12: 46929 | G12: 1.2 | H12: 1.25 | I12: 0.08 | J12: 0.08 | K12: =C12-500000 -> 49500000 | L12: =C12-K12 -> 500000 | M12: =IF(AND($F12>=M$6-90,$F12<M$6),$L12,0) -> 0 | N12: =IF(AND($F12>=N$6-90,$F12<N$6),$L12,0) -> 0 | O12: =IF(AND($F12>=O$6-90,$F12<O$6),$L12,0) -> 0 | P12: =IF(AND($F12>=P$6-90,$F12<P$6),$L12,0) -> 0 | Q12: =IF(AND($F12>=Q$6-90,$F12<Q$6),$L12,0) -> 0 | R12: =IF(AND($F12>=R$6-90,$F12<R$6),$L12,0) -> 0 | S12: =IF(AND($F12>=S$6-90,$F12<S$6),$L12,0) -> 0 | T12: =IF(AND($F12>=T$6-90,$F12<T$6),$L12,0) -> 0 | ... AB12: =IF(AND($F12>=AB$6-90,$F12<AB$6),$L12,0) -> 0
B13: Lakeside Loft | C13: 40000000 | D13: 46964 | F13: 46964 | G13: 1.2 | H13: 1.7 | I13: 0.08 | J13: 0.08 | K13: =C13-500000 -> 39500000 | L13: =C13-K13 -> 500000 | M13: =IF(AND($F13>=M$6-90,$F13<M$6),$L13,0) -> 0 | N13: =IF(AND($F13>=N$6-90,$F13<N$6),$L13,0) -> 0 | O13: =IF(AND($F13>=O$6-90,$F13<O$6),$L13,0) -> 0 | P13: =IF(AND($F13>=P$6-90,$F13<P$6),$L13,0) -> 0 | Q13: =IF(AND($F13>=Q$6-90,$F13<Q$6),$L13,0) -> 0 | R13: =IF(AND($F13>=R$6-90,$F13<R$6),$L13,0) -> 0 | S13: =IF(AND($F13>=S$6-90,$F13<S$6),$L13,0) -> 0 | T13: =IF(AND($F13>=T$6-90,$F13<T$6),$L13,0) -> 0 | ... AB13: =IF(AND($F13>=AB$6-90,$F13<AB$6),$L13,0) -> 0
B14: Cedarstone Residences | C14: 50000000 | D14: 46969 | F14: 46969 | G14: 1.2 | H14: 1 | I14: 0.08 | J14: 0.08 | K14: =C14-500000 -> 49500000 | L14: =C14-K14 -> 500000 | M14: =IF(AND($F14>=M$6-90,$F14<M$6),$L14,0) -> 0 | N14: =IF(AND($F14>=N$6-90,$F14<N$6),$L14,0) -> 0 | O14: =IF(AND($F14>=O$6-90,$F14<O$6),$L14,0) -> 0 | P14: =IF(AND($F14>=P$6-90,$F14<P$6),$L14,0) -> 0 | Q14: =IF(AND($F14>=Q$6-90,$F14<Q$6),$L14,0) -> 0 | R14: =IF(AND($F14>=R$6-90,$F14<R$6),$L14,0) -> 0 | S14: =IF(AND($F14>=S$6-90,$F14<S$6),$L14,0) -> 0 | T14: =IF(AND($F14>=T$6-90,$F14<T$6),$L14,0) -> 0 | ... AB14: =IF(AND($F14>=AB$6-90,$F14<AB$6),$L14,0) -> 0
B15: The Skyline Enclave | C15: 50000000 | D15: 46977 | F15: 46977 | G15: 1.2 | H15: 1.1 | I15: 0.08 | J15: 0.08 | K15: =C15-500000 -> 49500000 | L15: =C15-K15 -> 500000 | M15: =IF(AND($F15>=M$6-90,$F15<M$6),$L15,0) -> 0 | N15: =IF(AND($F15>=N$6-90,$F15<N$6),$L15,0) -> 0 | O15: =IF(AND($F15>=O$6-90,$F15<O$6),$L15,0) -> 0 | P15: =IF(AND($F15>=P$6-90,$F15<P$6),$L15,0) -> 0 | Q15: =IF(AND($F15>=Q$6-90,$F15<Q$6),$L15,0) -> 0 | R15: =IF(AND($F15>=R$6-90,$F15<R$6),$L15,0) -> 0 | S15: =IF(AND($F15>=S$6-90,$F15<S$6),$L15,0) -> 0 | T15: =IF(AND($F15>=T$6-90,$F15<T$6),$L15,0) -> 0 | ... AB15: =IF(AND($F15>=AB$6-90,$F15<AB$6),$L15,0) -> 0
B16: The Belmont Edge | C16: 1000000 | D16: 47070 | F16: 47070 | G16: 1.2 | H16: 1.2 | I16: 0.08 | J16: 0.08 | K16: =C16-500000 -> 500000 | L16: =C16-K16 -> 500000 | M16: =IF(AND($F16>=M$6-90,$F16<M$6),$L16,0) -> 0 | N16: =IF(AND($F16>=N$6-90,$F16<N$6),$L16,0) -> 0 | O16: =IF(AND($F16>=O$6-90,$F16<O$6),$L16,0) -> 0 | P16: =IF(AND($F16>=P$6-90,$F16<P$6),$L16,0) -> 0 | Q16: =IF(AND($F16>=Q$6-90,$F16<Q$6),$L16,0) -> 0 | R16: =IF(AND($F16>=R$6-90,$F16<R$6),$L16,0) -> 0 | S16: =IF(AND($F16>=S$6-90,$F16<S$6),$L16,0) -> 0 | T16: =IF(AND($F16>=T$6-90,$F16<T$6),$L16,0) -> 0 | ... AB16: =IF(AND($F16>=AB$6-90,$F16<AB$6),$L16,0) -> 500000
B17: Total Quarterly Exposure | C17: =SUM(C7:C16) -> 441000000 | K17: =SUM(K7:K16) -> 436000000 | L17: =SUM(L7:L16) -> 5000000 | M17: =SUM(M7:M16) -> 0 | N17: =SUM(N7:N16) -> 0 | O17: =SUM(O7:O16) -> 0 | P17: =SUM(P7:P16) -> 0 | Q17: =SUM(Q7:Q16) -> 0 | R17: =SUM(R7:R16) -> 0 | ... AB17: =SUM(AB7:AB16) -> 500000
B18: Total Annual Exposure | P18: =SUM(M17:P17) -> 0 | T18: =SUM(Q17:T17) -> 500000 | X18: =SUM(U17:X17) -> 1000000 | AB18: =SUM(Y17:AB17) -> 3500000

Sheet PERPETUITY MIDDLEMAN INPUT TAB
B2: Model Type | C2: Acquistions
B3: Asset Management Model Start | E3: Senior Loan Terms | H3: Sources and Uses
F4: Asset Mangement | H4: Total Sources
B5: Actuals Through | C5: =C11 -> 45346 | E5: Loan to Cost % | F5: ='Sample Model Tab'!E17 -> 0.6 | H5: Senior Loan | J5: =J19*F5 -> 20872774
B6: Date AM Model Starts | C6: =EOMONTH(C5,1) -> 45382 | E6: Interest Type - Fixed/Floating | F6: ='Sample Model Tab'!E18 -> Floating-Rate | H6: Preferred Equity | J6: =IF(C93="no",0,J19*C94-J5) -> 0
B7: Month AM Model Starts | C7: =ROUNDUP((C5-C11)/30.5,0) -> 0 | E7: Curve | F7: SOFR | H7: Investor Equity | J7: =(J19-J6-J5)*I45 -> 13219424
E8: SOFR Spread | F8: ='Sample Model Tab'!E19 -> 0.03 | H8: Ace Development Equity | J8: =J19-J7-J6-J5 -> 695759.14
B9: Construction and Delivery Schedule | E9: SOFR Floor | F9: 0 | H9: Total Sources | J9: =SUM(J5:J8) -> 34787957
C10: Active Case | E10: SOFR Cap | F10: 1
B11: Transaction Closing Date | C11: ='Sample Model Tab'!B37 -> 45346 | E11: Interest Only Period | F11: 24 | H11: Total Uses
B12: Construction Start Date | C12: =C11 -> 45346 | E12: Amortization Schedule | F12: 30 | H12: Land
B13: Construction Start Month | C13: 1 | E13: Initial Term | F13: ='Sample Model Tab'!E21 -> 24 | H13: Land | J13: ='Sample Model Tab'!I22 -> 10000000
B14: Construction Period | C14: 24 | E14: Loan Maturity | F14: =EOMONTH(C11,F13) -> 46081 | H14: Hard Costs | J14: ='Sample Model Tab'!I24 -> 19350000
B15: Construction Completion | C15: =C13+C14 -> 25 | E15: Origination Fee | F15: ='Sample Model Tab'!E20 -> 0.01 | H15: Soft Costs | J15: ='Sample Model Tab'!I23+'Sample Model Tab'!I25+'Sample Model Tab'!I26 -> 4000347.1
B16: First Units Delivered (Opex Starts) | C16: ='Sample Model Tab'!B27 -> 14 | E16: Rate Stepdown DSCR | F16: 0 | H16: Financing Costs | J16: ='Sample Model Tab'!I29 -> 208727.74
B17: Absorption Start | C17: ='Sample Model Tab'!B27 -> 14 | E17: Rate Stepdown DY | F17: 0 | H17: Operating Reserve | J17: ='Sample Model Tab'!I30 -> 71548.645
B18: Last Units Delivered | C18: =C14 -> 24 | E18: Stepdown Rate | F18: 0 | H18: Senior Interest Reserve | J18: ='Sample Model Tab'!I27 -> 1157333.3
E19: Exit Month | F19: 0 | H19: Total Uses | J19: =SUM(J13:J18) -> 34787957
B20: Revenue and Other Income | E20: Exit Fee | F20: 0
C21: Active Case | H21: Market
B22: Vacancy | C22: ='Sample Model Tab'!P48 -> 0.03 | E22: Exit Assumptions | H22: Unit Type | I22: # of Units | J22: Avg. SF | K22: Rent | L22: PSF
B23: Loss to Lease | C23: 0 | H23: ='Sample Model Tab'!L17 -> 1BR/1BA | I23: ='Sample Model Tab'!K17 -> 50 | J23: ='Sample Model Tab'!M17 -> 600 | K23: ='Sample Model Tab'!N17 -> 1425 | L23: =K23/J23 -> 2.375
B24: Bad Debt | C24: ='Sample Model Tab'!L49 -> 0.01 | E24: Sale Date | F24: =HLOOKUP(F25,'Cash Flow - AM'!$F$3:$DV$5,3) -> 48273 | H24: ='Sample Model Tab'!L18 -> 2BR/1BA | I24: ='Sample Model Tab'!K18 -> 20 | J24: ='Sample Model Tab'!M18 -> 725 | K24: ='Sample Model Tab'!N18 -> 1600 | L24: =K24/J24 -> 2.2068966
B25: Model Units | C25: 0 | E25: Sale Month | F25: ='Sample Model Tab'!I45 -> 96 | H25: ='Sample Model Tab'!L19 -> 2BR/2BA | I25: ='Sample Model Tab'!K19 -> 65 | J25: ='Sample Model Tab'!M19 -> 875 | K25: ='Sample Model Tab'!N19 -> 1875 | L25: =K25/J25 -> 2.1428571
E26: NOI Type | F26: F12 | H26: ='Sample Model Tab'!L20 -> 3BR/2BA | I26: ='Sample Model Tab'!K20 -> 10 | J26: ='Sample Model Tab'!M20 -> 1025 | K26: ='Sample Model Tab'!N20 -> 2100 | L26: =K26/J26 -> 2.0487805
B27: Concessions - Lease Up (New) | C27: 1 | E27: Sale Costs % | F27: ='Sample Model Tab'!I43 -> 0.01
B28: Concessions - Lease Up (Renewal) | C28: 0 | E28: Exit Capitalization Rate (MF) | F28: ='Sample Model Tab'!I44 -> 0.06
B29: Concessions - Stabilized (New) | C29: 0 | E29: Exit Capitalization (Retail) | F29: 0.06 | H29: Total / Avg - Market | I29: =IFERROR(SUM(I23:I28),0) -> 145 | J29: =IFERROR(SUMPRODUCT(I23:I28,J23:J28)/I29,0) -> 769.82759 | K29: =SUMPRODUCT(I23:I26,K23:K26)/I29 -> 1697.4138 | L29: =K29/J29 -> 2.2049272
B30: Concessions - Stabilized (Renewal) | C30: 0
E31: Tax Reassessment at Exit
H32: Inflation Indexes
B33: Absorption Start Month | C33: =C16 -> 14 | E33: Reassess at Sale | F33: Yes | I33: 1 | J33: =I33+1 -> 2 | K33: =J33+1 -> 3 | L33: =K33+1 -> 4 | M33: =L33+1 -> 5 | N33: =M33+1 -> 6 | O33: =N33+1 -> 7 | P33: =O33+1 -> 8
B34: Absorption Start Date | C34: =EOMONTH(C11,C16) -> 45777 | E34: Property Tax Millage Rate | F34: ='Sample Model Tab'!L94 -> 0.012 | I34: =I33 -> 1 | J34: =J33 -> 2 | K34: =K33 -> 3 | L34: =L33 -> 4 | M34: =M33 -> 5 | N34: =N33 -> 6 | O34: =O33 -> 7 | P34: =P33 -> 8
E35: County Assessment % | F35: 1 | H35: Market Rent Growth | I35: ='Sample Model Tab'!L54 -> 0.022 | J35: ='Sample Model Tab'!M54 -> 0.023 | K35: ='Sample Model Tab'!N54 -> 0.024 | L35: ='Sample Model Tab'!O54 -> 0.025 | M35: ='Sample Model Tab'!P54 -> 0.026 | N35: ='Sample Model Tab'!Q54 -> 0 | O35: ='Sample Model Tab'!R54 -> 0 | P35: ='Sample Model Tab'!S54 -> 0
B36: Leased Units Per Month | C36: 25 | E36: Market Value as % of Sale Price | F36: ='Sample Model Tab'!L96 -> 1 | H36: Affordable Rent Growth | I36: =I35 -> 0.022 | J36: =J35 -> 0.023 | K36: =K35 -> 0.024 | L36: =L35 -> 0.025 | M36: =M35 -> 0.026 | N36: =N35 -> 0 | O36: =O35 -> 0 | P36: =P35 -> 0
B37: Renewal Probability | C37: 0.5 | E37: Tax Adjusted Exit Cap Rate (MF) | F37: =F28+(F34*F35*F36) -> 0.072 | H37: Other Income Growth | I37: ='Sample Model Tab'!L55 -> 0.03 | J37: ='Sample Model Tab'!M55 -> 0.03 | K37: ='Sample Model Tab'!N55 -> 0.03 | L37: ='Sample Model Tab'!O55 -> 0.03 | M37: ='Sample Model Tab'!P55 -> 0.03 | N37: ='Sample Model Tab'!Q55 -> 0 | O37: ='Sample Model Tab'!R55 -> 0 | P37: ='Sample Model Tab'!S55 -> 0
B38: Lease Term | C38: 12 | H38: Controllables Growth | I38: ='Sample Model Tab'!$L$75 -> 0.02 | J38: ='Sample Model Tab'!$L$75 -> 0.02 | K38: ='Sample Model Tab'!$L$75 -> 0.02 | L38: ='Sample Model Tab'!$L$75 -> 0.02 | M38: ='Sample Model Tab'!$L$75 -> 0.02 | N38: ='Sample Model Tab'!$L$75 -> 0.02 | O38: ='Sample Model Tab'!$L$75 -> 0.02 | P38: ='Sample Model Tab'!$L$75 -> 0.02
H39: Taxes Growth | I39: ='Sample Model Tab'!$L$75 -> 0.02 | J39: ='Sample Model Tab'!$L$75 -> 0.02 | K39: ='Sample Model Tab'!$L$75 -> 0.02 | L39: ='Sample Model Tab'!$L$75 -> 0.02 | M39: ='Sample Model Tab'!$L$75 -> 0.02 | N39: ='Sample Model Tab'!$L$75 -> 0.02 | O39: ='Sample Model Tab'!$L$75 -> 0.02 | P39: ='Sample Model Tab'!$L$75 -> 0.02
H40: Insurance Growth | I40: ='Sample Model Tab'!$L$75 -> 0.02 | J40: ='Sample Model Tab'!$L$75 -> 0.02 | K40: ='Sample Model Tab'!$L$75 -> 0.02 | L40: ='Sample Model Tab'!$L$75 -> 0.02 | M40: ='Sample Model Tab'!$L$75 -> 0.02 | N40: ='Sample Model Tab'!$L$75 -> 0.02 | O40: ='Sample Model Tab'!$L$75 -> 0.02 | P40: ='Sample Model Tab'!$L$75 -> 0.02
B41: Operating Expenses
...

Sheet Model Sample Mapping-->

Sheet Summary
A1: Executive Summary
A3: Levered IRR of 10.2% | Equity Multiple: 1.89x| Net Profit: $12,501,952
G6: Property Details | K6: Return Metrics
G7: Number of Units | I7: 145 | K7: Unlevered IRR | M7: 0.082008585
G8: Number of Buildings | I8: 10 | K8: Unlevered Equity Multiple | M8: 1.6757444
G9: Net Rentals SF | I9: 111625 | K9: Levered IRR | M9: 0.10224795
G10: Average Unit Size SF | I10: 769.82759 | K10: Levered Equity Multiple | M10: 1.8851549
G11: Net Acres | I11: 9.5 | K11: Net Profit (Levered CF) | M11: 12501952
G12: Units per Acre | I12: 15.263158 | K12: Average Cash-on-Cash Return | M12: 0.046482859
G13: Street Address | I13: 555 Main Street | K13: LP IRR | M13: 0.098957175
G14: City/State/ZIP | I14: Santa Barbara, CA | K14: GP IRR | M14: 0.15388624
K15: LP Equity Multiple | M15: 1.8453206
G16: Sources of Funds (Construction Financing) | K16: GP Equity Multiple | M16: 2.6420068
G17: Equity | H17: 13915183 | I17: 0.4
G18: Mezzanine Loan | H18: 0 | I18: 0 | K18: Optimal Sale Year | M18: IRR
G19: Construction Loan | H19: 20872774 | I19: 0.6 | K19: Unlevered Acquisition | L19: 3 | M19: 0.12260577
G20: Total | H20: 34787957 | I20: 1 | K20: Levered Acquisition | L20: 3 | M20: 0.16055372
G22: Uses of Funds (Construction Period) | K22: Equity Structure
G23: Land Acquisition Costs | H23: 10000000 | I23: 0.2874558 | K23: GP Equity | M23: 0.05
G24: Closing Costs | H24: 100000 | I24: 0.002874558 | K24: LP Equity | M24: 0.95
G25: Hard Costs | H25: 19350000 | I25: 0.55622698
G26: Soft Costs | H26: 1786679.2 | I26: 0.051359129 | K26: LP CF's Distribuitions | L26: CFs | M26: % CF
G27: Contingency | H27: 2113667.9 | I27: 0.06075861 | K27: Prefered Return Hurdle | L27: 21909578 | M27: 0.95
G28: Capitalized Construction Interest | H28: 1157333.3 | I28: 0.033268218 | K28: Hurdle #2 | L28: 2850612.3 | M28: 0.8
G29: Mezzanine capitalized Interest | H29: 0 | I29: 0 | K29: Hurdle #3 | L29: 0
G30: Construction Loan Fees | H30: 208727.74 | I30: 0.006 | K30: Hurdle #4 | L30: 0
G31: Operating Expense Shortfalls | H31: 71548.645 | I31: 0.0020567073 | K31: Total LP CFs | L31: 24760190 | M31: 0.929926
G32: Total | H32: 34787957 | I32: 1
K33: GP CF Distributions | L33: CFs | M33: % CF
G34: Sales Details | K34: Prefered Return Hurdle | L34: 1153135.7 | M34: 0.05
G35: Sales Prices | I35: 41195530 | K35: Hurdle #2 | L35: 712653.08 | M35: 0.2
G36: Sales Price/Unit | I36: 284107.1 | K36: Hurdle #3 | L36: 0
G37: Cost of Sale | I37: 411955.3 | K37: Hurdle #4 | L37: 0
G38: Closing Costs (as % Sale Price) | I38: 0.01 | K38: Total GP CFs | L38: 1865788.7 | M38: 0.070073997
G39: Exist Cap Rate | I39: 0.06
G40: Hold Period | I40: 96
A50: Revenue vs NOI (Millions USD) | G50: Levered IRR per Holding Period (from Stabilization to 10 Years Holding)
A68: Cash Flows (Millions USD) | G68: Levered Cash Flow (Millions USD)
A86: Total Project Cost By Month (millions USD)
A105: Total Project Cost By Month (millions USD)

Sheet Sample Model Tab
A1: Assumptions
A2: 555 Main Street, Santa Barbara, CA
A3: Levered IRR of 14.0% | Equity Multiple: 2.40x| Net Profit: $19,901,814
L6: Carry Costs | N6: Pasted Values | O6: Formula (to be used by a macro)
L7: Capitalized Construction Interest | N7: 1157333.3 | O7: 1157333.3
L8: Mezzanine Loan | N8: 0 | O8: 0
L9: Mezzanine Loan Fees | N9: 0 | O9: 0
A10: Contents | L10: Construction Loan Fees | N10: 208727.74 | O10: 208727.74
A11: Circuit Breaker | L11: Operating Shortfall | N11: 71548.645 | O11: 71548.645
A12: On/Off | B12: Off
Q13: The model is configured to perform automatic calculations, with the exception of the data table.
K14: Revenue Section | Q14: To update the data table, the user must either save the file or manually press F9 for the changes to take effect.
A15: Property Details | D15: Construction Financing Amount | G15: Sources of Funds (Construction Financing) | K15: Stabilized Rents | Q15: Effect of Holding Period & Exit Cap on Levered IRR / Equity Multiple
A16: Number of Units | B16: 145 | D16: Construction Loan Amount | E16: 20872774 | G16: Equity | I16: 13915183 | K16: # of Units | L16: Unit Type | M16: SF | N16: Rent/Month | O16: Rent/SF | Q16: 14.0% / 2.40x | R16: 0.085 | S16: 0.08 | T16: 0.075 | U16: 0.07 | V16: 0.065 | W16: 0.06
A17: Number of Buildings | B17: 10 | D17: Loan to Cost (LTC) | E17: 0.6 | G17: Mezzanine Loan | I17: 0 | K17: 50 | L17: 1BR/1BA | M17: 600 | N17: 1425 | O17: 2.375 | Q17: 36 | R17: -30.8% / 0.41x | S17: -23.4% / 0.51x | T17: -16.7% / 0.63x | U17: -10.3% / 0.75x | V17: -4.1% / 0.89x | W17: 2.1% / 1.06x
A18: Net Rentals SF | B18: 111625 | D18: Fixed or Floating Rate? | E18: Floating-Rate | G18: Construction Loan | I18: 20872774 | K18: 20 | L18: 2BR/1BA | M18: 725 | N18: 1600 | O18: 2.2068966 | Q18: 48 | R18: -18.1% / 0.54x | S18: -12.9% / 0.64x | T18: -8.0% / 0.76x | U18: -3.4% / 0.89x | V18: 1.0% / 1.04x | W18: 5.5% / 1.20x
A19: Average Unit Size SF | B19: 769.82759 | D19: Fixed Rate/Interest Rate Spread | E19: 0.03 | G19: Total | I19: 34787957 | K19: 65 | L19: 2BR/2BA | M19: 875 | N19: 1875 | O19: 2.1428571 | Q19: 60 | R19: -9.4% / 0.69x | S19: -5.7% / 0.79x | T19: -2.2% / 0.91x | U19: 1.2% / 1.05x | V19: 4.4% / 1.20x | W19: 7.7% / 1.37x
A20: Net Acres | B20: 9.5 | D20: Loan Fee (as Percentage of Proceeds | E20: 0.01 | K20: 10 | L20: 3BR/2BA | M20: 1025 | N20: 2100 | O20: 2.0487805 | Q20: 72 | R20: -4.0% / 0.83x | S20: -1.3% / 0.94x | T20: 1.3% / 1.06x | U20: 3.9% / 1.20x | V20: 6.4% / 1.36x | W20: 8.9% / 1.54x
A21: Units per Acre | B21: 15.263158 | D21: Terms | E21: 24 | G21: Uses of Funds (Construction Period) | Q21: 84 | R21: -0.3% / 0.98x | S21: 1.7% / 1.10x | T21: 3.7% / 1.22x | U21: 5.7% / 1.36x | V21: 7.7% / 1.52x | W21: 9.7% / 1.71x
A22: Street Address | B22: 555 Main Street | G22: Land Acquisition Costs | I22: 10000000 | Q22: 96 | R22: 2.2% / 1.14x | S22: 3.8% / 1.26x | T22: 5.4% / 1.39x | U22: 7.0% / 1.53x | V22: 8.6% / 1.70x | W22: 10.2% / 1.89x
A23: City/State/ZIP | B23: Santa Barbara, CA | D23: Permanent Financing Information | G23: Closing Costs | I23: 100000 | Q23: 108 | R23: 4.1% / 1.31x | S23: 5.4% / 1.43x | T23: 6.7% / 1.56x | U23: 8.0% / 1.71x | V23: 9.3% / 1.88x | W23: 10.6% / 2.07x
A24: Currency | B24: USD | D24: Month | E24: 24 | G24: Hard Costs | I24: 19350000 | Q24: 120 | R24: 5.5% / 1.48x | S24: 6.6% / 1.61x | T24: 7.6% / 1.74x | U24: 8.7% / 1.90x | V24: 9.7% / 2.07x | W24: 10.9% / 2.27x
D25: Loan Amount | E25: 23939952 | G25: Soft Costs | I25: 1786679.2
A26: Lease-Up Information | D26: NOI at Permanent Refinancing Month | E26: 2074795.8 | G26: Contingency | I26: 2113667.9
A27: Lease-up Period Begins | B27: 14 | D27: Cap Rate Used for Valuation | E27: 0.065 | G27: Capitalized Construction Interest | I27: 1157333.3
A28: Property Stabilization | B28: 32 | D28: Loan to Value | E28: 0.75 | G28: Mezzanine capitalized Interest | I28: 0
A29: Lease-up Period | B29: 18 | D29: Going Debt Service Cover Ratio | E29: 1.2890971 | G29: Construction Loan Fees | I29: 208727.74 | K29: 145 | M29: 769.82759 | N29: 1697.4138 | O29: 2.2049272
D30: Going-in Debt Yield | E30: 0.086666667 | G30: Operating Expense Shortfalls | I30: 71548.645
A31: Land Acquisition Information | D31: Fixed or Floating Rate? | E31: Floating-Rate | G31: Total | I31: 34787957 | K31: Stabilized Other Income
A32: Land Acquisition Price | B32: 10000000 | D32: Fixed Rate/Interest Rate Spread | E32: 0.02 | K32: Item | M32: $/Unit/Month | N32: $/Month | O32: $/Year
A33: Land Price/Acre | B33: 1052631.6 | D33: Interest-Only Period | E33: 12 | G33: Total Costs Details | K33: Laundry Income | M33: 10 | N33: 1450 | O33: 17400
A34: Land Price/SF | B34: 24.165096 | D34: Loan Fee (as Percentage of Proceeds | E34: 0.01 | G34: Total Project Cost | I34: 34787957 | K34: Late Fees | M34: 3 | N34: 435 | O34: 5220
A35: Closing Costs(% of Land Price) | B35: 0.01 | D35: Amortization | E35: 360 | G35: Total Project Cost/Unit | I35: 239916.94 | K35: Pet Rent | M35: 15 | N35: 2175 | O35: 26100
A36: Closing Costs | B36: 100000 | D36: Term | E36: 96 | G36: Stabilized Return on Cost | I36: 0.069333311 | K36: Pet Fees | M36: 5 | N36: 725 | O36: 8700
A37: Land Closing Date | B37: 45346 | D37: Refince Permanet Debt | E37: N | G37: Cost /SF | I37: 311.65023 | K37: Garage Income | M37: 50 | N37: 7250 | O37: 87000
K38: Storage Income | M38: 0 | N38: 0 | O38: 0
A39: Refinancing debt Information | G39: Sales Details | K39: Other Charges | M39: 0 | N39: 0 | O39: 0
A40: Refinance Month | B40: 60 | D40: Mezzanine Construction Loan: | G40: Sales Prices | I40: 49434636 | K40: Other Charges | M40: 0 | N40: 0 | O40: 0
A41: NOI Used | B41: Trailing 12-month | D41: Mezzanine Debt? | E41: N | G41: Sales Price/Unit | I41: 340928.52 | K41: Other Charges | M41: 0 | N41: 0 | O41: 0
A42: NOI at Permanent Refinancing Month | B42: 2527672.6 | D42: Mezzanine Loan-to-Cost (LTC) Ratio: | E42: 0.1 | G42: Cost of Sale | I42: 494346.36 | K42: Other Charges | M42: 0 | N42: 0 | O42: 0
...

Sheet Sample AI QUESTIONS
B2: Question | C2: Answer | D2: Source 1 | E2: Source 2 | F2: Source 3
B3: What is the project basis? | C3: =_xlfn.CONCAT("The project basis is ",TEXT(D3,"$0,0")," per unit.") -> The project basis is $239,917 per unit. | D3: ='POC OUTPUT'!I23 -> 239916.94
B4: What is the land basis? | C4: =_xlfn.CONCAT("The land basis is ",TEXT(D4,"$0,0")," per unit.") -> The land basis is $68,966 per unit. | D4: ='POC OUTPUT'!I26 -> 68965.517
B5: When does the senior loan mature? | C5: =_xlfn.CONCAT("The senior loan matures on ",TEXT(D5,"mm/dd/yyy"),".") -> The senior loan matures on 02/28/2026. | D5: ='PERPETUITY MIDDLEMAN INPUT TAB'!F14 -> 46081
B6: When did the transaction close: | C6: =_xlfn.CONCAT("The deal closed on ",TEXT(D6,"mm/dd/yyy"),".") -> The deal closed on 02/24/2024. | D6: ='PERPETUITY MIDDLEMAN INPUT TAB'!C11 -> 45346
B7: What is the expected IRR and MOIC for this investment? | C7: =_xlfn.CONCAT("The expected IRR is ",TEXT(D7,"0.0%")," and MOIC is a ",TEXT(E7,"0.0x"),".") -> The expected IRR is 4.9% and MOIC is a 1.5x. | D7: ='POC OUTPUT'!L29 -> 0.048843762 | E7: ='POC OUTPUT'!L30 -> 1.4622176
B8: What is the expected sale price? | C8: =_xlfn.CONCAT("The expected sale price is ",TEXT(D8,"$0,0")," per unit.") -> The expected sale price is $255,136 per unit. | D8: ='POC OUTPUT'!N23 -> 255135.96
B9: What is the expected sale date? | C9: =_xlfn.CONCAT("The senior loan matures on ",TEXT(D9,"mm/dd/yyy"),".") -> The senior loan matures on 02/29/2032. | D9: ='POC OUTPUT'!N19 -> 48273
B10: What are the senior loan terms? | C10: =_xlfn.CONCAT("The senior loan is ",TEXT(D10,"0.0%")," LTC priced at ",E10," ",TEXT(F10,"0.0%"),".") -> The senior loan is 60.0% LTC priced at SOFR 3.0%. | D10: ='PERPETUITY MIDDLEMAN INPUT TAB'!F5 -> 0.6 | E10: ='PERPETUITY MIDDLEMAN INPUT TAB'!F7 -> SOFR | F10: ='PERPETUITY MIDDLEMAN INPUT TAB'!F8 -> 0.03

Sheet Issues List
B2: Mistakes In Model
B3: Fix concessions driving revenue negative
B4: Fix bad debt for the same problem
B5: These are dupes | C5: ='PERPETUITY MIDDLEMAN INPUT TAB'!C14+'PERPETUITY MIDDLEMAN INPUT TAB'!C18 -> 48
B6: Fixed Pet rent monthly / annua
B7: Built Retail Tab | C7: ='Income Statement - AM'!C67 -> 13451.25
B12: Edge Cases
B13: Cost Recoups in WF | C13: =SUM('AIRR Input Tab'!K21:O26) -> 11.63
B14: Lookbacks
B18: Seasonalized move in
B19: Opex Ramp | C19: ='Income Statement - AM'!D70 -> 0

Sheet Model Variants
B3: AIRR Model Variants by Property Type and Deal Type
B4: Property Type | C4: Residential (Multifamily, Build to Rent, Student Housing) | D4: Commercial (Office, Industrial, Retail) | F4: Self Storage | G4: Hotel | H4: For Sale (Land, Condo, Homes) | I4: Total Models
D5: Excel-Based | E5: Argus - Based
B6: Acquistion Deal | C6: 1 | D6: 1 | E6: 1 | F6: 1 | G6: 1 | H6: 1 | I6: =SUM(C6:H6) -> 6
B7: Development Deal | C7: 1 | D7: 1 | E7: 1 | F7: 1 | G7: 1 | H7: 1 | I7: =SUM(C7:H7) -> 6
B8: Total Models | C8: =SUM(C6:C7) -> 2 | D8: =SUM(D6:D7) -> 2 | E8: =SUM(E6:E7) -> 2 | F8: =SUM(F6:F7) -> 2 | G8: =SUM(G6:G7) -> 2 | H8: =SUM(H6:H7) -> 2 | I8: =SUM(C8:H8) -> 12

Sheet GUIDES FOR GEN AI LABS-->

Sheet MODEL GUIDE
B2: Model Variations Across Property Types
B3: Overview of Model Tabs
B4: Input Tab
B5: Deal Overview | C5: This tab contains all the general details about the transaction - what, where, who.
B6: Assumptions Tab | C6: This is the central nervous system of the model. This tab houses all construction, operating, and sale assumptions.
B7: Unit Mix and Other Income | C7: This tab drives the rent/revenue assumptions for the model.
B9: Actuals
B10: Balance Sheet | C10: These historical financials are sent to the analyst monthly (PDF, excel) and are currently populated by hand. They will need to be automatically ingested / populated into AIRR.
B11: Income Statement | C11: These historical financials are sent to the analyst monthly (PDF, excel) and are currently populated by hand. They will need to be automatically ingested / populated into AIRR.
B12: Draws | C12: These historical financials are sent to the analyst monthly (PDF, excel) and are currently populated by hand. They will need to be automatically ingested / populated into AIRR.
B14: Summary Ouputs | C14: These are the summary dashboards of the model. The will pull data from the inputs tabs as well as the model tabs below.
B16: AIRR Asset Management Model
B17: Income Statement - Revenue / Expenses | C17: These tabs will pull in historical actuals from the tabs above and blend it with a new CF forecast through sale that is driven by the input tabs.
B18: Cash Flow Tab | C18: These tabs will pull in historical actuals from the tabs above and blend it with a new CF forecast through sale that is driven by the input tabs.
B19: Waterfall | C19: These tabs will pull in historical actuals from the tabs above and blend it with a new CF forecast through sale that is driven by the input tabs.
B21: Underwriting
B22: Income Statement - Revenue / Expenses | C22: These tabs will run the assumptions of the original underwriting model and stay static so that the AIRR asset management model can be compared to the original underwriting.
B23: Cash Flow Tab | C23: These tabs will run the assumptions of the original underwriting model and stay static so that the AIRR asset management model can be compared to the original underwriting.
B24: Waterfall | C24: These tabs will run the assumptions of the original underwriting model and stay static so that the AIRR asset management model can be compared to the original underwriting.
B26: Model Variations Across Property Types - The table below details how the model will vary across different property types. This model is for multifamily.
B27: Overview of Model Tabs | C27: AI Populates Data | D27: Multifamily | E27: Build for Rent | F27: Student Housing | G27: Self Storage | H27: Industrial / IOS - Excel | I27: Industrial - Argus | J27: Office - Argus | K27: Retail - Argus | L27: Hotel | M27: For Sale (Land, Condo, Homes)
B28: Input Tab
B29: Deal Overview | C29: Here | D29: Same
B30: Assumptions Tab | C30: Here | D30: Same | H30: Industrial / IOS | I30: Similar | L30: Hotel Excel | M30: For Sale Excel
B32: Actuals
B33: Balance Sheet | C33: Here | D33: Same / Simliar
B34: Income Statement
B35: Draws
B37: Summary Ouputs | D37: Same | H37: Industrial / IOS | J37: Similar | L37: Hotel | M37: For Sale Excel
B39: AIRR Asset Management Model
B40: Income Statement - Revenue / Expenses | D40: Same | H40: Industrial / IOS | I40: Argus Cash Flow | L40: Hotel Excel | M40: For Sale Excel
B41: Cash Flow Tab | D41: Same | M41: For Sale Excel
B42: Waterfall | D42: Same
B44: Underwriting
B45: Income Statement - Revenue / Expenses | D45: Similar | H45: Industrial / IOS | I45: Argus Cash Flow | L45: Hotel Excel | M45: For Sale Excel
B46: Cash Flow Tab | D46: Same | M46: For Sale Excel
B47: Waterfall | D47: Same
B49: Note: Argus is a dominant software platform used to model the operating cash flows of large commercial office buildings and retail. It has limited modeling functionaity beyond the operating cash flows. Users will be able to take the Argus operating cash flow excel tab and drop it into AIRR.

Sheet POC OUTPUT
K8: Property Details
K10: Deal Name | N10: ='AIRR Input Tab'!D17 -> West Village Complexes
K11: Property Type | N11: Multifamily
K12: Closing Date | N12: ='PERPETUITY MIDDLEMAN INPUT TAB'!C11 -> 45346
K13: City | N13: 555 Main Street
K14: State | N14: Santa Barbara, CA
K15: Number of Units | N15: 145
F17: Budget | K17: Exit Assumptions
F19: Sources | G19: $ | H19: % | I19: Per Unit | K19: Sale Date | N19: ='PERPETUITY MIDDLEMAN INPUT TAB'!F24 -> 48273
F20: Senior Loan | G20: ='PERPETUITY MIDDLEMAN INPUT TAB'!J5 -> 20872774 | H20: =G20/$G$23 -> 0.6 | I20: =G20/$N$15 -> 143950.17 | K20: Sale Month | N20: ='PERPETUITY MIDDLEMAN INPUT TAB'!F25 -> 96
F21: LP Equity | G21: ='PERPETUITY MIDDLEMAN INPUT TAB'!J7 -> 13219424 | H21: =$G$23/$G$23 -> 1 | I21: =G21/$N$15 -> 91168.438 | K21: Exit Capitalization (MF) | N21: ='PERPETUITY MIDDLEMAN INPUT TAB'!F28 -> 0.06
F22: GP Equity | G22: ='PERPETUITY MIDDLEMAN INPUT TAB'!J8 -> 695759.14 | H22: =$G$23/$G$23 -> 1 | I22: =G22/$N$15 -> 4798.3389 | K22: Sale Price | N22: ='AIRR Model Summary'!E50 -> 36994714
F23: Total Uses | G23: =SUM(G20:G22) -> 34787957 | H23: =H22 -> 1 | I23: =SUM(I20:I22) -> 239916.94 | K23: Sale Price / Unit | N23: =N22/N15 -> 255135.96
F25: Uses | G25: $ | H25: % | I25: Per Unit | K25: Returns
F26: Land | G26: ='PERPETUITY MIDDLEMAN INPUT TAB'!J13 -> 10000000 | H26: =G26/$G$32 -> 0.2874558 | I26: =G26/$N$15 -> 68965.517
F27: Hard Costs | G27: ='PERPETUITY MIDDLEMAN INPUT TAB'!J14 -> 19350000 | H27: =G27/$G$32 -> 0.55622698 | I27: =G27/$N$15 -> 133448.28 | L27: ='AIRR Model Summary'!J67 -> Levered | M27: ='AIRR Model Summary'!K67 -> Investar | N27: ='AIRR Model Summary'!L67 -> Ace
F28: Soft Costs | G28: ='PERPETUITY MIDDLEMAN INPUT TAB'!J15 -> 4000347.1 | H28: =G28/$G$32 -> 0.1149923 | I28: =G28/$N$15 -> 27588.601 | K28: Investment | L28: ='AIRR Model Summary'!J68 -> 14850077 | M28: ='AIRR Model Summary'!K68 -> 14107573 | N28: ='AIRR Model Summary'!L68 -> 742503.86
F29: Financing Costs | G29: ='PERPETUITY MIDDLEMAN INPUT TAB'!J16 -> 208727.74 | H29: =G29/$G$32 -> 0.006 | I29: =G29/$N$15 -> 1439.5017 | K29: IRR | L29: ='AIRR Model Summary'!J69 -> 0.048843762 | M29: ='AIRR Model Summary'!K69 -> 0.046859661 | N29: ='AIRR Model Summary'!L69 -> 0.082324043
F30: Operating Reserve | G30: ='PERPETUITY MIDDLEMAN INPUT TAB'!J17 -> 71548.645 | H30: =G30/$G$32 -> 0.0020567073 | I30: =G30/$N$15 -> 493.43893 | K30: MOIC | L30: ='AIRR Model Summary'!J70 -> 1.4622176 | M30: ='AIRR Model Summary'!K70 -> 1.440323 | N30: ='AIRR Model Summary'!L70 -> 1.8782134
F31: Senior Interest Reserve | G31: ='PERPETUITY MIDDLEMAN INPUT TAB'!J18 -> 1157333.3 | H31: =G31/$G$32 -> 0.033268218 | I31: =G31/$N$15 -> 7981.6091 | K31: Net Profit | L31: ='AIRR Model Summary'!J71 -> 6863967.6 | M31: ='AIRR Model Summary'!K71 -> 6211890.8 | N31: ='AIRR Model Summary'!L71 -> 652076.88
F32: Total Uses | G32: =SUM(G26:G31) -> 34787957 | H32: =SUM(H26:H31) -> 1 | I32: =SUM(I26:I31) -> 239916.94 | K32: Exit / Unit | L32: ='AIRR Model Summary'!J72 -> 255135.96 | M32: ='AIRR Model Summary'!K72 -> 255135.96 | N32: ='AIRR Model Summary'!L72 -> 255135.96
K46: Exit Assumptions
K50: NOI Type | L50: F12
K51: Sale Costs % | L51: 0.02
K52: Exit Capitalization Rate (MF) | L52: 0.0475

Sheet Trailing Financial Statements->

Sheet Actuals Income Statement
B2: Income Statement
B3: Month | D3: ='Income Statement - AM'!D3 -> 0 | E3: ='Income Statement - AM'!E3 -> 1 | F3: ='Income Statement - AM'!F3 -> 2 | G3: ='Income Statement - AM'!G3 -> 3 | H3: ='Income Statement - AM'!H3 -> 4 | I3: ='Income Statement - AM'!I3 -> 5 | J3: ='Income Statement - AM'!J3 -> 6 | K3: ='Income Statement - AM'!K3 -> 7 | ... DT3: ='Income Statement - AM'!DT3 -> 120
B4: Year | D4: ='Income Statement - AM'!D4 -> 0 | E4: ='Income Statement - AM'!E4 -> 1 | F4: ='Income Statement - AM'!F4 -> 1 | G4: ='Income Statement - AM'!G4 -> 1 | H4: ='Income Statement - AM'!H4 -> 1 | I4: ='Income Statement - AM'!I4 -> 1 | J4: ='Income Statement - AM'!J4 -> 1 | K4: ='Income Statement - AM'!K4 -> 1 | ... DT4: ='Income Statement - AM'!DT4 -> 10
B5: Date | D5: ='Income Statement - AM'!D5 -> 45346 | E5: ='Income Statement - AM'!E5 -> 45382 | F5: ='Income Statement - AM'!F5 -> 45412 | G5: ='Income Statement - AM'!G5 -> 45443 | H5: ='Income Statement - AM'!H5 -> 45473 | I5: ='Income Statement - AM'!I5 -> 45504 | J5: ='Income Statement - AM'!J5 -> 45535 | K5: ='Income Statement - AM'!K5 -> 45565 | ... DT5: ='Income Statement - AM'!DT5 -> 49003
B7: Rental Income
B8: 400000 | C8: Gross Potential Rent | D8: 232800 | E8: 232800 | F8: 232758 | G8: 212640 | H8: 212640 | I8: 270720 | J8: 270720 | K8: 270720 | L8: 270720 | M8: 270720 | N8: 270720 | O8: 270720
B9: 401000 | C9: Vacancy | D9: -106215 | E9: -107670 | F9: -100395 | G9: -96205 | H9: -108589 | I9: -138799 | J9: -137877 | K9: -133066 | L9: -129720 | M9: -126502 | N9: -124201 | O9: -140506
B10: 401200 | C10: Vacancy Loss - Model | D10: -1940 | E10: -1940 | F10: -1940 | G10: -1772 | H10: -1772 | I10: -2256 | J10: -2256 | K10: -2256 | L10: -2256 | M10: -2256 | N10: -2256 | O10: -2256
B11: 401500 | C11: No-Prorate Credits | D11: 0 | E11: 0 | F11: 0 | G11: 0 | H11: 0 | I11: 0 | J11: 0 | K11: 0 | L11: 0 | M11: 0 | N11: 0 | O11: -100
B12: 401600 | C12: Gain/Loss to Lease | D12: 21952 | E12: -8763 | F12: -5615.21 | G12: 6317.3 | H12: 16132.3 | I12: -3834 | J12: -2401 | K12: -6937 | L12: -6994 | M12: -5875 | N12: -6484 | O12: 1422
B13: 401700 | C13: Staff/Employee Accommodations | D13: -5335 | E13: -5380 | F13: -7275 | G13: -6249.3 | H13: -6249.3 | I13: -5494 | J13: -5993 | K13: -5993 | L13: -5993 | M13: -5993 | N13: -5993 | O13: -6798.32
B14: 402800 | C14: Bad Debt | D14: -28217.9 | E14: -11342.78 | F14: 6216.16 | G14: -14109.32 | H14: -52409.86 | I14: -35395.06 | J14: -30726.85 | K14: -37481.54 | L14: -18926.83 | M14: -29778.06 | N14: -16636.49 | O14: -28882.9
B15: 403000 | C15: Bad Debt Recovered | D15: 0 | E15: 1464 | F15: 0 | G15: 0 | H15: 2530.02 | I15: 0 | J15: 8071.3 | K15: 0 | L15: 0 | M15: 0 | N15: 0 | O15: 0
B16: 403200 | C16: Concessions-Recurring | D16: 0 | E16: -45 | F16: 90 | G16: 0 | H16: 0 | I16: -6899 | J16: -7339 | K16: -8069 | L16: -8129 | M16: -8449 | N16: -8161 | O16: -9417
B17: 403300 | C17: Concessions-One Time | D17: -1299 | E17: 0 | F17: 0 | G17: -500 | H17: -1098.36 | I17: -1640 | J17: 0 | K17: 0 | L17: 0 | M17: 0 | N17: 0 | O17: 0
B24: Total Rental Income | D24: =SUM(D8:D23) -> 111745.1 | E24: =SUM(E8:E23) -> 99123.22 | F24: =SUM(F8:F23) -> 123838.95 | G24: =SUM(G8:G23) -> 100121.68 | H24: =SUM(H8:H23) -> 61183.8 | I24: =SUM(I8:I23) -> 76402.94 | J24: =SUM(J8:J23) -> 92198.45 | K24: =SUM(K8:K23) -> 76917.46 | ... DT24: =SUM(DT8:DT23) -> 0
B27: Other Income
B28: 403500 | C28: Parking Permit-Contract | D28: 0 | E28: 0 | F28: 0 | G28: 1125 | H28: 0 | I28: 0 | J28: 0 | K28: 0 | L28: 0 | M28: 0 | N28: 0 | O28: 0
B29: 407500 | C29: Utility Income | D29: 8560.1 | E29: 23907.52 | F29: 17724.9 | G29: 11987.72 | H29: 12067.49 | I29: 58340.65 | J29: 12665.53 | K29: 12876.35 | L29: 17356.81 | M29: 24665.91 | N29: 20998.29 | O29: 20788.5
B30: 412100 | C30: Damages/Resident Bill Backs | D30: 925 | E30: 3070.73 | F30: 8.29 | G30: 0 | H30: 8825 | I30: 4410 | J30: 3030 | K30: 5045 | L30: 990 | M30: 3850 | N30: 895 | O30: 2790
B31: 412300 | C31: Lease Charges | D31: 0 | E31: 2001 | F31: 0 | G31: 0 | H31: 0 | I31: 0 | J31: 0 | K31: 0 | L31: 0 | M31: 0 | N31: 804.47 | O31: 500
B32: 412700 | C32: Insurance Waiver Program Income | D32: 3196.07 | E32: 2984 | F32: 2116.46 | G32: 3090 | H32: 3495 | I32: 2655 | J32: 2820 | K32: 3105 | L32: 2640 | M32: 2820 | N32: 2745 | O32: 2850
B33: 412800 | C33: Guarantor Waiver Program Income | D33: 690 | E33: 828 | F33: 930 | G33: 864 | H33: 972 | I33: 0 | J33: 0 | K33: 0 | L33: 0 | M33: 0 | N33: 0 | O33: 0
B34: 412900 | C34: Credit Reporting Program Income | D34: 0 | E34: 0 | F34: -7 | G34: 7 | H34: 7 | I34: -147 | J34: 49 | K34: 42 | L34: 35 | M34: 21 | N34: 0 | O34: 0
B35: 413000 | C35: Late Fees | D35: 5499.06 | E35: 4966.95 | F35: 4650.73 | G35: -162.5 | H35: 2535 | I35: 4057.08 | J35: 3645.42 | K35: 3315 | L35: 3282.5 | M35: 2795 | N35: 3380 | O35: 4030
B36: 413500 | C36: NSF Fees | D36: 20 | E36: -10 | F36: 100 | G36: 20 | H36: 50 | I36: 50 | J36: 0 | K36: 0 | L36: 0 | M36: -50 | N36: 50 | O36: 0
B37: 414000 | C37: Miscellaneous Income | D37: 235.34 | E37: 1589.7 | F37: 480 | G37: -330 | H37: 2640 | I37: 390 | J37: 156.32 | K37: 0 | L37: 120 | M37: 120 | N37: 120 | O37: 365.06
B38: 415500 | C38: Application Fees | D38: -319 | E38: 380.45 | F38: 258 | G38: 4300 | H38: 100 | I38: 0 | J38: 0 | K38: 0 | L38: 0 | M38: 0 | N38: 0 | O38: 0
B39: 415700 | C39: Lease Termination Fees | D39: 0 | E39: 0 | F39: 0 | G39: 0 | H39: 5000 | I39: 5250 | J39: 2250 | K39: 3750 | L39: 750 | M39: 2585 | N39: 849 | O39: 750
B50: Total Other Income | D50: =SUM(D28:D49) -> 18806.57 | E50: =SUM(E28:E49) -> 39718.35 | F50: =SUM(F28:F49) -> 26261.38 | G50: =SUM(G28:G49) -> 20901.22 | H50: =SUM(H28:H49) -> 35691.49 | I50: =SUM(I28:I49) -> 75005.73 | J50: =SUM(J28:J49) -> 24616.27 | K50: =SUM(K28:K49) -> 28133.35 | ... DT50: =SUM(DT28:DT49) -> 0
B52: Effective Gross Income (Total) | D52: =D24+D50 -> 130551.67 | E52: =E24+E50 -> 138841.57 | F52: =F24+F50 -> 150100.33 | G52: =G24+G50 -> 121022.9 | H52: =H24+H50 -> 96875.29 | I52: =I24+I50 -> 151408.67 | J52: =J24+J50 -> 116814.72 | K52: =K24+K50 -> 105050.81 | ... DT52: =DT24+DT50 -> 0
B55: Payroll and Benefits
B56: 650100 | C56: Admin Salaries | D56: 8242.86 | E56: 7047.96 | F56: 8618.36 | G56: 7310.54 | H56: 8458.26 | I56: 8797.51 | J56: 9461.46 | K56: 6272 | L56: 5261 | M56: 7081.5 | N56: 5665 | O56: 6271
B57: 650200 | C57: Maintenance Salaries | D57: 4366.53 | E57: 4560.67 | F57: 4112.2 | G57: 3634.79 | H57: 3499.23 | I57: 4052.6 | J57: 4994.7 | K57: 5815.71 | L57: 2754.98 | M57: 3688.93 | N57: 2812.36 | O57: 3921.78
B58: 650300 | C58: Leasing Salaries | D58: 2221.2 | E58: 2228.44 | F58: 4065 | G58: 3621.5 | H58: 2859.3 | I58: 2616 | J58: 2734.45 | K58: 2908.35 | L58: 2181.5 | M58: 3104.4 | N58: 2255.3 | O58: 3666.55
B59: 650400 | C59: Res Life Salaries | D59: 939.91 | E59: 871.35 | F59: 0 | G59: -440.33 | H59: 1403.54 | I59: 630.49 | J59: 1002.03 | K59: 486.85 | L59: 752 | M59: 1100.42 | N59: 2438.55 | O59: 1364.25
B60: 650700 | C60: Overtime | D60: 62.37 | E60: 339.58 | F60: 651.21 | G60: 375.27 | H60: 2450.72 | I60: 1192.37 | J60: 470.93 | K60: 910.32 | L60: 1026.29 | M60: 583.41 | N60: 746.41 | O60: 800.19
B61: 653100 | C61: Admin Taxes and Benefits | D61: 3861.69 | E61: 2242 | F61: 2398.49 | G61: 1730.56 | H61: 2437.4 | I61: 2708.83 | J61: 2848.96 | K61: 1805.99 | L61: 1752.47 | M61: 1879.57 | N61: 1719.85 | O61: 1978.4
B62: 653200 | C62: Maintenance Taxes and Benefits | D62: 1651.99 | E62: 1763.62 | F62: 1493.09 | G62: 1025.59 | H62: 1780.05 | I62: 1703.37 | J62: 1763.17 | K62: 1769.59 | L62: 1440.13 | M62: 1235.76 | N62: 1405.01 | O62: 1503.15
B63: 653300 | C63: Leasing Taxes and Benefits | D63: 382.89 | E63: 349.32 | F63: 685.81 | G63: 571.49 | H63: 557 | I63: 795.77 | J63: 522.01 | K63: 581.61 | L63: 543.77 | M63: 484.83 | N63: 459.02 | O63: 658.8
...

Sheet Actual Rent Roll
B2: Rent Roll
L3: Scheduled Charges
B4: Unit # | C4: Floorplan | D4: Occupied | E4: Market/Affordable | F4: Classic / Renovated | G4: Name | H4: Lease Start | I4: Lease End | J4: SF | K4: Market Rent | L4: Rent | M4: CONC-RECURRIN | N4: RENTERS INS | O4: EMETSCHOLAR | P4: EMPLCREDLOSS | Q4: PET RENT | R4: Total Billing
B5: 111A | C5: 4x4 | D5: ='Sample RR'!K4 -> Occupied | E5: N/A | F5: N/A | G5: ='Sample RR'!M4 -> Coutee, Gabriel | H5: 45048 | I5: 45777 | J5: 325 | K5: 564 | L5: 544 | M5: -45 | N5: 15 | O5: 0 | P5: 0 | Q5: 0 | R5: =SUM(L5:Q5) -> 514 | S5: ='Sample RR'!AK4-R5 -> 0
B6: ='Sample RR'!A7 -> 111B | C6: ='Sample RR'!C7 -> 4x4 | D6: ='Sample RR'!K7 -> Occupied | E6: N/A | F6: N/A | G6: ='Sample RR'!M7 -> Brown, Ceasar | H6: ='Sample RR'!T7 -> 44775 | I6: ='Sample RR'!V7 -> 45138 | J6: ='Sample RR'!I7 -> 325 | K6: ='Sample RR'!Y7 -> 564 | L6: ='Sample RR'!AF8 -> 519 | M6: ='Sample RR'!AH7 -> -10 | N6: 0 | O6: 0 | P6: 0 | Q6: 0 | R6: =SUM(L6:Q6) -> 509 | S6: ='Sample RR'!AK7-R6 -> 0
B7: ='Sample RR'!A9 -> 111C | C7: ='Sample RR'!C9 -> 4x4 | D7: ='Sample RR'!K9 -> Occupied | E7: N/A | F7: N/A | G7: ='Sample RR'!M9 -> Walker, Taliayah | H7: ='Sample RR'!T9 -> 44775 | I7: ='Sample RR'!V9 -> 45138 | J7: ='Sample RR'!I9 -> 325 | K7: ='Sample RR'!Y9 -> 564 | L7: ='Sample RR'!AF10 -> 534 | M7: ='Sample RR'!AH9 -> -35 | N7: 0 | O7: 0 | P7: 0 | Q7: 0 | R7: =SUM(L7:Q7) -> 499 | S7: ='Sample RR'!AK9-R7 -> 0
B8: ='Sample RR'!A11 -> 111D | C8: ='Sample RR'!C11 -> 4x4 | D8: ='Sample RR'!K11 -> Occupied | E8: N/A | F8: N/A | G8: ='Sample RR'!M11 -> Jones, Travonn | H8: ='Sample RR'!T11 -> 44783 | I8: ='Sample RR'!V11 -> 45138 | J8: ='Sample RR'!I11 -> 325 | K8: ='Sample RR'!Y11 -> 564 | L8: ='Sample RR'!AF12 -> 544 | M8: ='Sample RR'!AH11 -> -45 | N8: ='Sample RR'!AH13 -> 15 | O8: 0 | P8: 0 | Q8: 0 | R8: =SUM(L8:Q8) -> 514 | S8: ='Sample RR'!AK11-R8 -> 0
B9: ='Sample RR'!A14 -> 112A | C9: ='Sample RR'!C14 -> 4x4 | D9: ='Sample RR'!K14 -> Occupied | E9: N/A | F9: N/A | G9: ='Sample RR'!M14 -> Smith, Tyeryka | H9: ='Sample RR'!T14 -> 44776 | I9: ='Sample RR'!V14 -> 45138 | J9: ='Sample RR'!I14 -> 325 | K9: ='Sample RR'!Y14 -> 564 | L9: ='Sample RR'!AF15 -> 544 | M9: ='Sample RR'!AH14 -> -45 | N9: ='Sample RR'!AH16 -> 15 | O9: 0 | P9: 0 | Q9: 0 | R9: =SUM(L9:Q9) -> 514 | S9: ='Sample RR'!AK14-R9 -> 0
B10: ='Sample RR'!A17 -> 112B | C10: ='Sample RR'!C17 -> 4x4 | D10: ='Sample RR'!K17 -> Occupied | E10: N/A | F10: N/A | G10: ='Sample RR'!M17 -> Brown, ShaRron | H10: ='Sample RR'!T17 -> 44774 | I10: ='Sample RR'!V17 -> 45138 | J10: ='Sample RR'!I17 -> 325 | K10: ='Sample RR'!Y17 -> 564 | L10: ='Sample RR'!AF18 -> 549 | M10: ='Sample RR'!AH17 -> -50 | N10: ='Sample RR'!AH19 -> 15 | O10: 0 | P10: 0 | Q10: 0 | R10: =SUM(L10:Q10) -> 514 | S10: ='Sample RR'!AK17-R10 -> 0
B11: ='Sample RR'!A20 -> 112C | C11: ='Sample RR'!C20 -> 4x4 | D11: ='Sample RR'!K20 -> Occupied | E11: N/A | F11: N/A | G11: ='Sample RR'!M20 -> Carter, Kyla | H11: ='Sample RR'!T20 -> 44805 | I11: ='Sample RR'!V20 -> 45138 | J11: ='Sample RR'!I20 -> 325 | K11: ='Sample RR'!Y20 -> 564 | L11: ='Sample RR'!AF21 -> 549 | M11: ='Sample RR'!AH20 -> -50 | N11: 0 | O11: 0 | P11: 0 | Q11: 0 | R11: =SUM(L11:Q11) -> 499 | S11: ='Sample RR'!AK20-R11 -> 0
B12: ='Sample RR'!A22 -> 112D | C12: ='Sample RR'!C22 -> 4x4 | D12: ='Sample RR'!K22 -> Occupied | E12: N/A | F12: N/A | G12: ='Sample RR'!M22 -> Norton, Daysia | H12: ='Sample RR'!T22 -> 44866 | I12: ='Sample RR'!V22 -> 45138 | J12: ='Sample RR'!I22 -> 325 | K12: ='Sample RR'!Y22 -> 564 | L12: ='Sample RR'!AF23 -> 534 | M12: ='Sample RR'!AH22 -> -35 | N12: ='Sample RR'!AH24 -> 15 | O12: 0 | P12: 0 | Q12: 0 | R12: =SUM(L12:Q12) -> 514 | S12: ='Sample RR'!AK22-R12 -> 0
B13: ='Sample RR'!A25 -> 113A | C13: ='Sample RR'!C25 -> 4x4 | D13: ='Sample RR'!K25 -> Vacant | E13: N/A | F13: N/A | G13: ='Sample RR'!M25 -> VACANT | H13: ='Sample RR'!T25 -> 0 | I13: ='Sample RR'!V25 -> 0 | J13: ='Sample RR'!I25 -> 325 | K13: ='Sample RR'!Y25 -> 564 | L13: ='Sample RR'!AF26 -> 0 | M13: ='Sample RR'!AH25 -> 0 | N13: 0 | O13: 0 | P13: 0 | Q13: 0 | R13: =SUM(L13:Q13) -> 0 | S13: ='Sample RR'!AK25-R13 -> 0
B14: ='Sample RR'!A26 -> 113B | C14: ='Sample RR'!C26 -> 4x4 | D14: ='Sample RR'!K26 -> Vacant | E14: N/A | F14: N/A | G14: ='Sample RR'!M26 -> VACANT | H14: ='Sample RR'!T26 -> 0 | I14: ='Sample RR'!V26 -> 0 | J14: ='Sample RR'!I26 -> 325 | K14: ='Sample RR'!Y26 -> 564 | L14: ='Sample RR'!AF27 -> 0 | M14: ='Sample RR'!AH26 -> 0 | N14: ='Sample RR'!AH28 -> 0 | O14: 0 | P14: 0 | Q14: 0 | R14: =SUM(L14:Q14) -> 0 | S14: ='Sample RR'!AK26-R14 -> 0
B15: ='Sample RR'!A27 -> 113C | C15: ='Sample RR'!C27 -> 4x4 | D15: ='Sample RR'!K27 -> Occupied | E15: N/A | F15: N/A | G15: ='Sample RR'!M27 -> Gibson $, Raykivus | H15: ='Sample RR'!T27 -> 44774 | I15: ='Sample RR'!V27 -> 45138 | J15: ='Sample RR'!I27 -> 325 | K15: ='Sample RR'!Y27 -> 564 | L15: ='Sample RR'!AF28 -> 534 | M15: ='Sample RR'!AH27 -> -35 | N15: ='Sample RR'!AH29 -> 15 | O15: 0 | P15: 0 | Q15: 0 | R15: =SUM(L15:Q15) -> 514 | S15: ='Sample RR'!AK27-R15 -> 0
B16: ='Sample RR'!A30 -> 113D | C16: ='Sample RR'!C30 -> 4x4 | D16: ='Sample RR'!K30 -> Occupied | E16: N/A | F16: N/A | G16: ='Sample RR'!M30 -> Caldwell, Ronald | H16: ='Sample RR'!T30 -> 44774 | I16: ='Sample RR'!V30 -> 45138 | J16: ='Sample RR'!I30 -> 325 | K16: ='Sample RR'!Y30 -> 564 | L16: ='Sample RR'!AF36 -> 544 | M16: ='Sample RR'!AH30 -> -45 | N16: ='Sample RR'!AH37 -> 15 | O16: ='Sample RR'!AH31 -> -249 | P16: 0 | Q16: ='Sample RR'!AH32 -> 30 | R16: =SUM(L16:Q16) -> 295 | S16: ='Sample RR'!AK30-R16 -> 0
B17: ='Sample RR'!A38 -> 114A | C17: ='Sample RR'!C38 -> 4x4 | D17: ='Sample RR'!K38 -> Occupied | E17: N/A | F17: N/A | G17: ='Sample RR'!M38 -> Thomas, Christian | H17: ='Sample RR'!T38 -> 44776 | I17: ='Sample RR'!V38 -> 45138 | J17: ='Sample RR'!I38 -> 325 | K17: ='Sample RR'!Y38 -> 564 | L17: ='Sample RR'!AF39 -> 544 | M17: ='Sample RR'!AH38 -> -45 | N17: ='Sample RR'!AH40 -> 15 | O17: 0 | P17: 0 | Q17: 0 | R17: =SUM(L17:Q17) -> 514 | S17: ='Sample RR'!AK38-R17 -> 0
B18: ='Sample RR'!A41 -> 114B | C18: ='Sample RR'!C41 -> 4x4 | D18: ='Sample RR'!K41 -> Occupied | E18: N/A | F18: N/A | G18: ='Sample RR'!M41 -> Fegans $, Antwon | H18: ='Sample RR'!T41 -> 44805 | I18: ='Sample RR'!V41 -> 45138 | J18: ='Sample RR'!I41 -> 325 | K18: ='Sample RR'!Y41 -> 564 | L18: ='Sample RR'!AF42 -> 544 | M18: ='Sample RR'!AH41 -> -45 | N18: ='Sample RR'!AH43 -> 15 | O18: 0 | P18: 0 | Q18: 0 | R18: =SUM(L18:Q18) -> 514 | S18: ='Sample RR'!AK41-R18 -> 0
B19: ='Sample RR'!A44 -> 114C | C19: ='Sample RR'!C44 -> 4x4 | D19: ='Sample RR'!K44 -> Vacant | E19: N/A | F19: N/A | G19: ='Sample RR'!M44 -> VACANT | H19: ='Sample RR'!T44 -> 0 | I19: ='Sample RR'!V44 -> 0 | J19: ='Sample RR'!I44 -> 325 | K19: ='Sample RR'!Y44 -> 564 | L19: ='Sample RR'!AF45 -> 0 | M19: ='Sample RR'!AH44 -> 0 | N19: 0 | O19: 0 | P19: 0 | Q19: 0 | R19: =SUM(L19:Q19) -> 0 | S19: ='Sample RR'!AK44-R19 -> 0
B20: ='Sample RR'!A45 -> 114D | C20: ='Sample RR'!C45 -> 4x4 | D20: ='Sample RR'!K45 -> Vacant | E20: N/A | F20: N/A | G20: ='Sample RR'!M45 -> VACANT | H20: ='Sample RR'!T45 -> 0 | I20: ='Sample RR'!V45 -> 0 | J20: ='Sample RR'!I45 -> 325 | K20: ='Sample RR'!Y45 -> 564 | L20: ='Sample RR'!AF46 -> 0 | M20: ='Sample RR'!AH45 -> 0 | N20: ='Sample RR'!AH47 -> 0 | O20: 0 | P20: 0 | Q20: 0 | R20: =SUM(L20:Q20) -> 0 | S20: ='Sample RR'!AK45-R20 -> 0
B21: ='Sample RR'!A46 -> 121A | C21: ='Sample RR'!C46 -> 4x4 | D21: ='Sample RR'!K46 -> Occupied | E21: N/A | F21: N/A | G21: ='Sample RR'!M46 -> McGuire, Chanquavion | H21: ='Sample RR'!T46 -> 44799 | I21: ='Sample RR'!V46 -> 45138 | J21: ='Sample RR'!I46 -> 325 | K21: ='Sample RR'!Y46 -> 564 | L21: ='Sample RR'!AF47 -> 544 | M21: ='Sample RR'!AH46 -> -45 | N21: ='Sample RR'!AH48 -> 15 | O21: 0 | P21: 0 | Q21: 0 | R21: =SUM(L21:Q21) -> 514 | S21: ='Sample RR'!AK46-R21 -> 0
B22: ='Sample RR'!A49 -> 121B | C22: ='Sample RR'!C49 -> 4x4 | D22: ='Sample RR'!K49 -> Occupied | E22: N/A | F22: N/A | G22: ='Sample RR'!M49 -> Webb, Dagan | H22: ='Sample RR'!T49 -> 44774 | I22: ='Sample RR'!V49 -> 45138 | J22: ='Sample RR'!I49 -> 325 | K22: ='Sample RR'!Y49 -> 564 | L22: ='Sample RR'!AF51 -> 544 | M22: ='Sample RR'!AH49 -> -45 | N22: ='Sample RR'!AH52 -> 15 | O22: ='Sample RR'!AH50 -> -249 | P22: 0 | Q22: 0 | R22: =SUM(L22:Q22) -> 265 | S22: ='Sample RR'!AK49-R22 -> 0
B23: ='Sample RR'!A53 -> 121C | C23: ='Sample RR'!C53 -> 4x4 | D23: ='Sample RR'!K53 -> Occupied | E23: N/A | F23: N/A | G23: ='Sample RR'!M53 -> Ikechukwu, Jeffrey | H23: ='Sample RR'!T53 -> 44774 | I23: ='Sample RR'!V53 -> 45138 | J23: ='Sample RR'!I53 -> 325 | K23: ='Sample RR'!Y53 -> 564 | L23: ='Sample RR'!AF54 -> 534 | M23: ='Sample RR'!AH53 -> -35 | N23: ='Sample RR'!AH55 -> 15 | O23: 0 | P23: 0 | Q23: 0 | R23: =SUM(L23:Q23) -> 514 | S23: ='Sample RR'!AK53-R23 -> 0
B24: ='Sample RR'!A56 -> 121D | C24: ='Sample RR'!C56 -> 4x4 | D24: ='Sample RR'!K56 -> Vacant | E24: N/A | F24: N/A | G24: ='Sample RR'!M56 -> VACANT | H24: ='Sample RR'!T56 -> 0 | I24: ='Sample RR'!V56 -> 0 | J24: ='Sample RR'!I56 -> 325 | K24: ='Sample RR'!Y56 -> 564 | L24: ='Sample RR'!AF57 -> 0 | M24: ='Sample RR'!AH56 -> 0 | N24: ='Sample RR'!AH58 -> 0 | O24: 0 | P24: 0 | Q24: 0 | R24: =SUM(L24:Q24) -> 0 | S24: ='Sample RR'!AK56-R24 -> 0
B25: ='Sample RR'!A57 -> 122A | C25: ='Sample RR'!C57 -> 4x4 | D25: ='Sample RR'!K57 -> Occupied | E25: N/A | F25: N/A | G25: ='Sample RR'!M57 -> Jones, Erica | H25: ='Sample RR'!T57 -> 44774 | I25: ='Sample RR'!V57 -> 45138 | J25: ='Sample RR'!I57 -> 325 | K25: ='Sample RR'!Y57 -> 564 | L25: ='Sample RR'!AF58 -> 519 | M25: ='Sample RR'!AH57 -> -25 | N25: ='Sample RR'!AH59 -> 15 | O25: 0 | P25: 0 | Q25: 0 | R25: =SUM(L25:Q25) -> 509 | S25: ='Sample RR'!AK57-R25 -> 0
B26: ='Sample RR'!A60 -> 122B | C26: ='Sample RR'!C60 -> 4x4 | D26: ='Sample RR'!K60 -> Vacant | E26: N/A | F26: N/A | G26: ='Sample RR'!M60 -> VACANT | H26: ='Sample RR'!T60 -> 0 | I26: ='Sample RR'!V60 -> 0 | J26: ='Sample RR'!I60 -> 325 | K26: ='Sample RR'!Y60 -> 564 | L26: ='Sample RR'!AF61 -> 0 | M26: ='Sample RR'!AH60 -> 0 | N26: ='Sample RR'!AH62 -> 0 | O26: 0 | P26: 0 | Q26: 0 | R26: =SUM(L26:Q26) -> 0 | S26: ='Sample RR'!AK60-R26 -> 0
B27: ='Sample RR'!A61 -> 122C | C27: ='Sample RR'!C61 -> 4x4 | D27: ='Sample RR'!K61 -> Occupied | E27: N/A | F27: N/A | G27: ='Sample RR'!M61 -> Calais, Tristan | H27: ='Sample RR'!T61 -> 44774 | I27: ='Sample RR'!V61 -> 45138 | J27: ='Sample RR'!I61 -> 325 | K27: ='Sample RR'!Y61 -> 564 | L27: ='Sample RR'!AF62 -> 544 | M27: ='Sample RR'!AH61 -> -45 | N27: ='Sample RR'!AH63 -> 15 | O27: 0 | P27: 0 | Q27: 0 | R27: =SUM(L27:Q27) -> 514 | S27: ='Sample RR'!AK61-R27 -> 0
B28: ='Sample RR'!A67 -> 122D | C28: ='Sample RR'!C67 -> 4x4 | D28: ='Sample RR'!K67 -> Occupied | E28: N/A | F28: N/A | G28: ='Sample RR'!M67 -> Hughes, Kierra | H28: ='Sample RR'!T67 -> 44805 | I28: ='Sample RR'!V67 -> 45138 | J28: ='Sample RR'!I67 -> 325 | K28: ='Sample RR'!Y67 -> 564 | L28: ='Sample RR'!AF68 -> 544 | M28: ='Sample RR'!AH67 -> -45 | N28: ='Sample RR'!AH69 -> 15 | O28: 0 | P28: 0 | Q28: 0 | R28: =SUM(L28:Q28) -> 514 | S28: ='Sample RR'!AK67-R28 -> 0
B29: ='Sample RR'!A70 -> 123A | C29: ='Sample RR'!C70 -> 4x4 | D29: ='Sample RR'!K70 -> Vacant | E29: N/A | F29: N/A | G29: ='Sample RR'!M70 -> VACANT | H29: ='Sample RR'!T70 -> 0 | I29: ='Sample RR'!V70 -> 0 | J29: ='Sample RR'!I70 -> 325 | K29: ='Sample RR'!Y70 -> 564 | L29: ='Sample RR'!AF71 -> 0 | M29: ='Sample RR'!AH70 -> 0 | N29: 0 | O29: 0 | P29: 0 | Q29: 0 | R29: =SUM(L29:Q29) -> 0 | S29: ='Sample RR'!AK70-R29 -> 0
B30: ='Sample RR'!A71 -> 123B | C30: ='Sample RR'!C71 -> 4x4 | D30: ='Sample RR'!K71 -> Vacant | E30: N/A | F30: N/A | G30: ='Sample RR'!M71 -> VACANT | H30: ='Sample RR'!T71 -> 0 | I30: ='Sample RR'!V71 -> 0 | J30: ='Sample RR'!I71 -> 325 | K30: ='Sample RR'!Y71 -> 564 | L30: ='Sample RR'!AF72 -> 0 | M30: ='Sample RR'!AH71 -> 0 | N30: ='Sample RR'!AH73 -> 0 | O30: 0 | P30: 0 | Q30: 0 | R30: =SUM(L30:Q30) -> 0 | S30: ='Sample RR'!AK71-R30 -> 0
B31: ='Sample RR'!A72 -> 123C | C31: ='Sample RR'!C72 -> 4x4 | D31: ='Sample RR'!K72 -> Occupied | E31: N/A | F31: N/A | G31: ='Sample RR'!M72 -> Valsin $, Jomard | H31: ='Sample RR'!T72 -> 44781 | I31: ='Sample RR'!V72 -> 45138 | J31: ='Sample RR'!I72 -> 325 | K31: ='Sample RR'!Y72 -> 564 | L31: ='Sample RR'!AF73 -> 549 | M31: ='Sample RR'!AH72 -> -50 | N31: ='Sample RR'!AH74 -> 15 | O31: 0 | P31: 0 | Q31: 0 | R31: =SUM(L31:Q31) -> 514 | S31: ='Sample RR'!AK72-R31 -> 0
B32: ='Sample RR'!A75 -> 123D | C32: ='Sample RR'!C75 -> 4x4 | D32: ='Sample RR'!K75 -> Vacant | E32: N/A | F32: N/A | G32: ='Sample RR'!M75 -> VACANT | H32: ='Sample RR'!T75 -> 0 | I32: ='Sample RR'!V75 -> 0 | J32: ='Sample RR'!I75 -> 325 | K32: ='Sample RR'!Y75 -> 564 | L32: ='Sample RR'!AF76 -> 0 | M32: ='Sample RR'!AH75 -> 0 | N32: ='Sample RR'!AH77 -> 0 | O32: 0 | P32: 0 | Q32: 0 | R32: =SUM(L32:Q32) -> 0 | S32: ='Sample RR'!AK75-R32 -> 0
B33: ='Sample RR'!A76 -> 124A | C33: ='Sample RR'!C76 -> 4x4 | D33: ='Sample RR'!K76 -> Occupied | E33: N/A | F33: N/A | G33: ='Sample RR'!M76 -> Ward, Hallie | H33: ='Sample RR'!T76 -> 44786 | I33: ='Sample RR'!V76 -> 45138 | J33: ='Sample RR'!I76 -> 325 | K33: ='Sample RR'!Y76 -> 564 | L33: ='Sample RR'!AF77 -> 544 | M33: ='Sample RR'!AH76 -> -45 | N33: ='Sample RR'!AH78 -> 15 | O33: 0 | P33: 0 | Q33: 0 | R33: =SUM(L33:Q33) -> 514 | S33: ='Sample RR'!AK76-R33 -> 0
B34: ='Sample RR'!A79 -> 124B | C34: ='Sample RR'!C79 -> 4x4 | D34: ='Sample RR'!K79 -> Occupied | E34: N/A | F34: N/A | G34: ='Sample RR'!M79 -> Tremie $, Elizabeth | H34: ='Sample RR'!T79 -> 44786 | I34: ='Sample RR'!V79 -> 45138 | J34: ='Sample RR'!I79 -> 325 | K34: ='Sample RR'!Y79 -> 564 | L34: ='Sample RR'!AF80 -> 544 | M34: ='Sample RR'!AH79 -> -45 | N34: ='Sample RR'!AH81 -> 15 | O34: 0 | P34: 0 | Q34: 0 | R34: =SUM(L34:Q34) -> 514 | S34: ='Sample RR'!AK79-R34 -> 0
B35: ='Sample RR'!A82 -> 124C | C35: ='Sample RR'!C82 -> 4x4 | D35: ='Sample RR'!K82 -> Occupied | E35: N/A | F35: N/A | G35: ='Sample RR'!M82 -> Lewis, Santana-Lin | H35: ='Sample RR'!T82 -> 44786 | I35: ='Sample RR'!V82 -> 45138 | J35: ='Sample RR'!I82 -> 325 | K35: ='Sample RR'!Y82 -> 564 | L35: ='Sample RR'!AF83 -> 519 | M35: ='Sample RR'!AH82 -> -25 | N35: ='Sample RR'!AH84 -> 15 | O35: 0 | P35: 0 | Q35: 0 | R35: =SUM(L35:Q35) -> 509 | S35: ='Sample RR'!AK82-R35 -> 0
B36: ='Sample RR'!A86 -> 124D | C36: ='Sample RR'!C86 -> 4x4 | D36: ='Sample RR'!K86 -> Vacant | E36: N/A | F36: N/A | G36: ='Sample RR'!M86 -> VACANT | H36: ='Sample RR'!T86 -> 0 | I36: ='Sample RR'!V86 -> 0 | J36: ='Sample RR'!I86 -> 325 | K36: ='Sample RR'!Y86 -> 564 | L36: ='Sample RR'!AF87 -> 0 | M36: ='Sample RR'!AH86 -> 0 | N36: ='Sample RR'!AH88 -> 0 | O36: 0 | P36: 0 | Q36: 0 | R36: =SUM(L36:Q36) -> 0 | S36: ='Sample RR'!AK86-R36 -> 0
B37: ='Sample RR'!A87 -> 131A | C37: ='Sample RR'!C87 -> 4x4 | D37: ='Sample RR'!K87 -> Vacant | E37: N/A | F37: N/A | G37: ='Sample RR'!M87 -> VACANT | H37: ='Sample RR'!T87 -> 0 | I37: ='Sample RR'!V87 -> 0 | J37: ='Sample RR'!I87 -> 325 | K37: ='Sample RR'!Y87 -> 564 | L37: ='Sample RR'!AF88 -> 0 | M37: ='Sample RR'!AH87 -> 0 | N37: ='Sample RR'!AH89 -> 0 | O37: 0 | P37: 0 | Q37: 0 | R37: =SUM(L37:Q37) -> 0 | S37: ='Sample RR'!AK87-R37 -> 0
B38: ='Sample RR'!A88 -> 131B | C38: ='Sample RR'!C88 -> 4x4 | D38: ='Sample RR'!K88 -> Vacant | E38: N/A | F38: N/A | G38: ='Sample RR'!M88 -> VACANT | H38: ='Sample RR'!T88 -> 0 | I38: ='Sample RR'!V88 -> 0 | J38: ='Sample RR'!I88 -> 325 | K38: ='Sample RR'!Y88 -> 564 | L38: ='Sample RR'!AF89 -> 0 | M38: ='Sample RR'!AH88 -> 0 | N38: ='Sample RR'!AH90 -> 0 | O38: 0 | P38: 0 | Q38: 0 | R38: =SUM(L38:Q38) -> 0 | S38: ='Sample RR'!AK88-R38 -> 0
B39: ='Sample RR'!A89 -> 131C | C39: ='Sample RR'!C89 -> 4x4 | D39: ='Sample RR'!K89 -> Vacant | E39: N/A | F39: N/A | G39: ='Sample RR'!M89 -> VACANT | H39: ='Sample RR'!T89 -> 0 | I39: ='Sample RR'!V89 -> 0 | J39: ='Sample RR'!I89 -> 325 | K39: ='Sample RR'!Y89 -> 564 | L39: ='Sample RR'!AF90 -> 0 | M39: ='Sample RR'!AH89 -> 0 | N39: ='Sample RR'!AH91 -> 0 | O39: 0 | P39: 0 | Q39: 0 | R39: =SUM(L39:Q39) -> 0 | S39: ='Sample RR'!AK89-R39 -> 0
